Workbook
Name Week2: 'thru 117'!$69:$69
Name Week2: '118+'!$77:$77
Name Week5: '118+'!$293:$293
Name Week3: 'thru 117'!$141:$141
Name Week1: 'thru 117'!$4:$4
Name Week1: '118+'!$5:$5
Name Week3: '118+'!$149:$149
Name Tempo: #REF!
Name Week4: 'thru 117'!$213:$213
Name Week4: '118+'!$221:$221
Name Week5: 'thru 117'!$285:$285

Sheet 118+
B1: =HYPERLINK("https://wa.me/13106587414?text=Hello%20Michal", "WhatsApp Me") -> WhatsApp Me | I1: =HYPERLINK("mailto:mfiala@fialafitness.com?subject=Training Inquiry", "Email Me") -> Email Me
C2: CURRENT WEEK | D2: JUMP TO: | T2: WORKOUTS IN JANUARY
C3: =IF(WEEKDAY(DATE(YEAR(TODAY()), MONTH(TODAY()), 1), 2) = 7, WEEKNUM(TODAY(), 2) - WEEKNUM(DATE(YEAR(TODAY()), MONTH(TODAY()), 2), 2) + 1, WEEKNUM(TODAY(), 2) - WEEKNUM(DATE(YEAR(TODAY()), MONTH(TODAY()), 1), 2) + 1) -> 5 | D3: WEEK 1 | F3: WEEK 2 | H3: WEEK 3 | K3: WEEK 4 | O3: WEEK 5
C4: Exercise | E4: Sets | F4: Reps | G4: Tempo | H4: Rest | I4: Weight (Lbs) | S4: PR | T4: Notes
B5: WEEK 1
B6: Session 1
C7: TRUE | E7: =IFS(C7=FALSE, "⬅️ Check when DONE", C7=TRUE, "☑️ Workout Completed", TRUE, "") -> ☑️ Workout Completed | I7: 1 | J7: 2 | K7: 3 | L7: 4 | M7: 5 | N7: 6 | O7: 7 | P7: 8 | Q7: 9 | R7: 10 | T7: 45675
B8: A | C8: Db bench press | E8: 4 | F8: 10 | I8: 55 | J8: 60 | K8: 60 | L8: 60
B9: A | C9: Tricep Dips | E9: 4 | F9: 10 | T9: Body weight
B10: B | C10: Flat DB Chest Flies | E10: 4 | F10: 10 | I10: 35 | J10: 35 | K10: 35 | L10: 35
B11: B | C11: Standing overhead single DB tricep behind head thingy | E11: 4 | F11: 10 | I11: 35 | J11: 35 | K11: 35 | L11: 35
C12: =IF(D12<>"", HYPERLINK(VLOOKUP(D12, DATA!H:K, 4, FALSE), D12), "")
C13: =IF(D13<>"", HYPERLINK(VLOOKUP(D13, DATA!H:K, 4, FALSE), D13), "")
C14: =IF(D14<>"", HYPERLINK(VLOOKUP(D14, DATA!H:K, 4, FALSE), D14), "")
C15: =IF(D15<>"", HYPERLINK(VLOOKUP(D15, DATA!H:K, 4, FALSE), D15), "")
B18: Session 2
C19: TRUE | E19: =IFS(C19=FALSE, "⬅️ Check when DONE", C19=TRUE, "☑️ Workout Completed", TRUE, "") -> ☑️ Workout Completed | I19: 1 | J19: 2 | K19: 3 | L19: 4 | M19: 5 | N19: 6 | O19: 7 | P19: 8 | Q19: 9 | R19: 10 | T19: 45676
B20: A | C20: DB Curls | E20: 4 | F20: 10 | I20: 35 | J20: 35 | K20: 35 | L20: 35
B21: C | C21: Hammer Curls | E21: 4 | F21: 10 | I21: 25 | J21: 25 | K21: 25 | L21: 25
B22: B | C22: Incline Dumbbell Row | E22: 4 | F22: 10 | I22: 50 | J22: 50 | K22: 50 | L22: 50
C24: =IF(D24<>"", HYPERLINK(VLOOKUP(D24, DATA!H:K, 4, FALSE), D24), "")
C25: =IF(D25<>"", HYPERLINK(VLOOKUP(D25, DATA!H:K, 4, FALSE), D25), "")
C26: =IF(D26<>"", HYPERLINK(VLOOKUP(D26, DATA!H:K, 4, FALSE), D26), "")
C27: =IF(D27<>"", HYPERLINK(VLOOKUP(D27, DATA!H:K, 4, FALSE), D27), "")
B30: Session 3
C31: TRUE | E31: =IFS(C31=FALSE, "⬅️ Check when DONE", C31=TRUE, "☑️ Workout Completed", TRUE, "") -> ☑️ Workout Completed | I31: 1 | J31: 2 | K31: 3 | L31: 4 | M31: 5 | N31: 6 | O31: 7 | P31: 8 | Q31: 9 | R31: 10 | T31: 45677
B32: A | C32: Squats | I32: 85 | J32: 95 | K32: 95 | L32: 95 | T32: rested muscles otherwise
C33: =IF(D33<>"", HYPERLINK(VLOOKUP(D33, DATA!H:K, 4, FALSE), D33), "")
C34: =IF(D34<>"", HYPERLINK(VLOOKUP(D34, DATA!H:K, 4, FALSE), D34), "")
C35: =IF(D35<>"", HYPERLINK(VLOOKUP(D35, DATA!H:K, 4, FALSE), D35), "")
C36: =IF(D36<>"", HYPERLINK(VLOOKUP(D36, DATA!H:K, 4, FALSE), D36), "")
C37: =IF(D37<>"", HYPERLINK(VLOOKUP(D37, DATA!H:K, 4, FALSE), D37), "")
C38: =IF(D38<>"", HYPERLINK(VLOOKUP(D38, DATA!H:K, 4, FALSE), D38), "")
C39: =IF(D39<>"", HYPERLINK(VLOOKUP(D39, DATA!H:K, 4, FALSE), D39), "")
B42: Session 4
C43: TRUE | E43: =IFS(C43=FALSE, "⬅️ Check when DONE", C43=TRUE, "☑️ Workout Completed", TRUE, "") -> ☑️ Workout Completed | I43: 1 | J43: 2 | K43: 3 | L43: 4 | M43: 5 | N43: 6 | O43: 7 | P43: 8 | Q43: 9 | R43: 10 | T43: 45681
B44: A | C44: Db bench press | E44: 4 | F44: 10 | I44: 55 | J44: 60 | K44: 60 | L44: 60
B45: A | C45: Tricep Dips | E45: 4 | F45: 10 | T45: Body weight
B46: B | C46: Flat DB Chest Flies | E46: 4 | F46: 10 | I46: 35 | J46: 35 | K46: 35 | L46: 35
B47: B | C47: Standing overhead single DB tricep behind head thingy | E47: 4 | F47: 10 | I47: 35 | J47: 35 | K47: 35 | L47: 35
...

Sheet thru 117
B1: =HYPERLINK("https://wa.me/13106587414?text=Hello%20Michal", "WhatsApp Me") -> WhatsApp Me | I1: =HYPERLINK("mailto:mfiala@fialafitness.com?subject=Training Inquiry", "Email Me") -> Email Me
C2: CURRENT WEEK | D2: JUMP TO: | S2: WORKOUTS IN JANUARY | T2: TOTAL WORKOUTS
C3: =IF(WEEKDAY(DATE(YEAR(TODAY()), MONTH(TODAY()), 1), 2) = 7, WEEKNUM(TODAY(), 2) - WEEKNUM(DATE(YEAR(TODAY()), MONTH(TODAY()), 2), 2) + 1, WEEKNUM(TODAY(), 2) - WEEKNUM(DATE(YEAR(TODAY()), MONTH(TODAY()), 1), 2) + 1) -> 5 | D3: WEEK 1 | F3: WEEK 2 | H3: WEEK 3 | K3: WEEK 4 | O3: WEEK 5
B4: WEEK 1
C5: TRUE | D5: =IFS(C5=FALSE, "Session 1", C5=TRUE, "Session 1 Completed", TRUE, "") -> Session 1 Completed | S5: 45575.47
C6: Exercise | E6: Sets | F6: Reps | G6: Tempo | H6: Rest | I6: Weight (Lbs) | S6: Notes | T6: Comments
B7: A | C7: =IF(D7<>"", HYPERLINK(VLOOKUP(D7, DATA!H:K, 4, FALSE), D7), "") -> Bicep Curl | D7: Bicep Curl | E7: 4 | F7: 45453 | G7: Normal | H7: 0s | I7: 25 | J7: 30 | K7: 35 | L7: 35 | M7: 35
B8: A | C8: =IF(D8<>"", HYPERLINK(VLOOKUP(D8, DATA!H:K, 4, FALSE), D8), "") -> Cable Overhead Triceps Extension | D8: Cable Overhead Triceps Extension | E8: 4 | F8: 45580 | G8: Normal | H8: 90s | I8: 50 | J8: 50 | K8: 60 | L8: 60 | M8: 70
B9: B | C9: =IF(D9<>"", HYPERLINK(VLOOKUP(D9, DATA!H:K, 4, FALSE), D9), "") -> Close Grip Bench Press | D9: Close Grip Bench Press | E9: 4 | F9: 45451 | G9: Normal | H9: 0s
B10: B | C10: =IF(D10<>"", HYPERLINK(VLOOKUP(D10, DATA!H:K, 4, FALSE), D10), "") -> Barbell Bicep Curl | D10: Barbell Bicep Curl | E10: 4 | F10: 45451 | G10: Normal | H10: 2 mins
C13: TRUE | D13: =IFS(C13=FALSE, "Session 2", C13=TRUE, "Session 2 Completed", TRUE, "") -> Session 2 Completed | S13: 45575.47
C14: Exercise | E14: Sets | F14: Reps | G14: Tempo | H14: Rest | I14: Weight (Lbs) | S14: Notes | T14: Comments
B15: A | C15: Incline Bench Row (45 degrees) | E15: 4 | F15: 10 | G15: Normal | H15: 0s | I15: 35 | J15: 35 | K15: 40
B16: A | C16: Lateral raise | E16: 4 | F16: 10 | G16: Normal | H16: 0s | I16: 10 | J16: 10 | K16: 15
B17: A | C17: Front raise | E17: 4 | F17: 10 | G17: Normal | H17: 60s | I17: 10 | J17: 10 | K17: 15
B18: B | C18: Dumbbell chest press | E18: 4 | F18: 10 | G18: Normal | H18: 90s | I18: 40 | J18: 40 | K18: 45
B19: B | C19: =IF(D19<>"", HYPERLINK(VLOOKUP(D19, DATA!H:K, 4, FALSE), D19), "") -> Barbell Bent Over Row | D19: Barbell Bent Over Row | E19: 4 | F19: 10 | G19: Normal | H19: 90s
C22: TRUE | D22: =IFS(C22=FALSE, "Session 3", C22=TRUE, "Session 3 Completed", TRUE, "") -> Session 3 Completed | S22: 45586
C23: Exercise | E23: Sets | F23: Reps | G23: Tempo | H23: Rest | I23: Weight (Lbs) | S23: Notes | T23: Comments
B24: A | C24: =IF(D24<>"", HYPERLINK(VLOOKUP(D24, DATA!H:K, 4, FALSE), D24), "") -> Barbell Close Grip Bench Press | D24: Barbell Close Grip Bench Press | E24: 4 | F24: 10 | G24: Normal | H24: 0s | T24: Bench press been too busy both days
B25: A | C25: =IF(D25<>"", HYPERLINK(VLOOKUP(D25, DATA!H:K, 4, FALSE), D25), "") -> Bicep Curl | D25: Bicep Curl | E25: 4 | F25: 10 | G25: Normal | H25: 2 mins | I25: 30 | J25: 35 | K25: 35 | L25: 35
B26: B | C26: =IF(D26<>"", HYPERLINK(VLOOKUP(D26, DATA!H:K, 4, FALSE), D26), "") -> Dips | D26: Dips | E26: 4 | F26: 10 | G26: Normal | H26: 0s
B27: B | C27: =IF(D27<>"", HYPERLINK(VLOOKUP(D27, DATA!H:K, 4, FALSE), D27), "") -> Hammer Curl | D27: Hammer Curl | E27: 4 | F27: 10 | G27: Normal | H27: 2 mins | I27: 30 | J27: 35 | K27: 35 | L27: 35
C29: =IF(D29<>"", HYPERLINK(VLOOKUP(D29, DATA!H:K, 4, FALSE), D29), "")
C30: =IF(D30<>"", HYPERLINK(VLOOKUP(D30, DATA!H:K, 4, FALSE), D30), "")
C31: =IF(D31<>"", HYPERLINK(VLOOKUP(D31, DATA!H:K, 4, FALSE), D31), "")
C34: TRUE | D34: =IFS(C34=FALSE, "Session 4", C34=TRUE, "Session 4 Completed", TRUE, "") -> Session 4 Completed | S34: 45587
C35: Exercise | E35: Sets | F35: Reps | G35: Tempo | H35: Rest | I35: Weight (Lbs) | S35: Notes | T35: Comments
B36: A | C36: pull-ups | E36: 10 | F36: max | G36: Normal | H36: 90s
C37: =IF(D37<>"", HYPERLINK(VLOOKUP(D37, DATA!H:K, 4, FALSE), D37), "")
C38: =IF(D38<>"", HYPERLINK(VLOOKUP(D38, DATA!H:K, 4, FALSE), D38), "")
C39: =IF(D39<>"", HYPERLINK(VLOOKUP(D39, DATA!H:K, 4, FALSE), D39), "")
C40: =IF(D40<>"", HYPERLINK(VLOOKUP(D40, DATA!H:K, 4, FALSE), D40), "")
C41: =IF(D41<>"", HYPERLINK(VLOOKUP(D41, DATA!H:K, 4, FALSE), D41), "")
C42: =IF(D42<>"", HYPERLINK(VLOOKUP(D42, DATA!H:K, 4, FALSE), D42), "")
C43: =IF(D43<>"", HYPERLINK(VLOOKUP(D43, DATA!H:K, 4, FALSE), D43), "")
C46: FALSE | D46: =IFS(C46=FALSE, "Session 5", C46=TRUE, "Session 5 Completed", TRUE, "") -> Session 5
C47: Exercise | E47: Sets | F47: Reps | G47: Tempo | H47: Rest | I47: Weight (Lbs) | S47: Notes | T47: Comments
C48: =IF(D48<>"", HYPERLINK(VLOOKUP(D48, DATA!H:K, 4, FALSE), D48), "")
C49: =IF(D49<>"", HYPERLINK(VLOOKUP(D49, DATA!H:K, 4, FALSE), D49), "")
...

Sheet Dashboard
B1: NAME
B2: TOTAL WORKOUTS 2024: | E2: =SUM(G4:G15) -> #REF!
C3: LEFT GRIP | D3: RIGHT GRIP | E3: WEIGHT (Lbs) | F3: BODY FAT | G3: WORKOUTS
B4: JANUARY | C4: 0 | D4: 0 | E4: 0 | F4: 0 | G4: =#REF! -> #REF!
B5: FEBRUARY | C5: 0 | D5: 0 | E5: 0 | F5: 0 | G5: =Feb!T3 -> #REF!
B6: MARCH | C6: 0 | D6: 0 | E6: 0 | F6: 0 | G6: =Mar!T3 -> #REF!
B7: APRIL | C7: 0 | D7: 0 | E7: 0 | F7: 0 | G7: =Apr!T3 -> #REF!
B8: MAY | C8: 0 | D8: 0 | E8: 0 | F8: 0 | G8: =May!T3 -> #REF!
B9: JUNE | C9: 0 | D9: 0 | E9: 0 | F9: 0 | G9: =Jun!T3 -> #REF!
B10: JULY | C10: 0 | D10: 0 | E10: 0 | F10: 0 | G10: =Jul!T3 -> #REF!
B11: AUGUST | C11: 0 | D11: 0 | E11: 0 | F11: 0 | G11: =Aug!T3 -> #REF!
B12: SEPTEMBER | C12: 0 | D12: 0 | E12: 0 | F12: 0 | G12: =Sep!T3 -> #REF!
B13: OCTOBER | C13: 0 | D13: 0 | E13: 0 | F13: 0 | G13: =Oct!T3 -> #REF!
B14: NOVEMBER | C14: 0 | D14: 0 | E14: 0 | F14: 0 | G14: =Nov!T3 -> #REF!
B15: DECEMBER | C15: 0 | D15: 0 | E15: 0 | F15: 0 | G15: =Dec!T3 -> #REF!
B63: Exercise TEMPO Guide: “Lowering-Pause-Lifting-Hold” 1. Lowering (Eccentric): • What it is: This phase represents the time it takes to lower the weight or your body during an exercise, also known as the eccentric phase. • Example: In a squat, this is the part where you slowly lower yourself down. • Time: The first number in the tempo indicates the seconds to lower. For example, “2” means you take 2 seconds to lower the weight. 2. Pause (Bottom): • What it is: This phase is the pause at the bottom of the movement, where you hold the position before starting to lift again. • Example: In a squat, this is the moment you pause at the lowest point of the squat. • Time: The second number shows how long you pause. For example, “3” means you hold for 3 seconds. 3. Lifting (Concentric): • What it is: This phase is the time it takes to lift the weight or your body back to the starting position, known as the concentric phase. • Example: In a squat, this is when you push yourself back up to a standing position. • Time: The third number indicates the time to lift. For example, “2” means you lift for 2 seconds. 4. Pause (Top): • What it is: This phase is the pause at the top of the movement, where you briefly hold the position before starting the next rep. • Example: In a squat, this is the moment you pause at the top after fully standing up. • Time: The fourth number shows how long you hold. For example, “1” means you hold for 1 second. Example: How to Use the 2321 Tempo If your workout plan includes a tempo of “2321,” here’s how to apply it: • Lowering: 2 seconds to lower the weight (eccentric). • Pause (Bottom): 3 seconds pause at the bottom of the movement. • Lifting: 2 seconds to lift the weight (concentric). • Pause (Top): 1 second hold at the top before the next rep.

Sheet DATA
J1: =MAX(J3:J1231) -> 1229
A2: Sets | B2: Reps | C2: Rest | E2: Tempo | F2: Session | H2: exercise_name | I2: exercise_focus | J2: library_id | K2: exercise_video_link | L2: exercise_description
A3: 1 | B3: 4 - 6 | C3: 0s | D3: A | E3: Normal | F3: 1 | H3: Ab Wheel Iso | I3: Core | J3: 1 | K3: https://www.youtube.com/watch?v=1vDicD_tr9M | L3: Hold ab wheel position for core engagement.
A4: 2 | B4: 6 - 8 | C4: 10s | D4: B | E4: Slow | F4: 2 | H4: Ab Wheel Rollout | I4: Core | J4: 2 | K4: https://www.youtube.com/watch?v=9ZCoAbI7uX0 | L4: Extend fully using ab wheel, engage core to return.
A5: 3 | B5: 8 - 10 | C5: 15s | D5: C | E5: 1111 | F5: 3 | H5: Adductor Mobilization | I5: Legs | J5: 3 | K5: https://www.youtube.com/watch?v=hS82gl2Ea8g | L5: Mobilize hip adductors for better flexibility.
A6: 4 | B6: 8 - 12 | C6: 30s | D6: D | E6: 1112 | F6: 4 | H6: Alternating Barbell Split Jump | I6: Legs | J6: 4 | K6: https://www.youtube.com/watch?v=fiFvoKrHxng | L6: Explosive split jump while alternating legs.
A7: 5 | B7: 12 - 15 | C7: 60s | D7: E | E7: 1113 | F7: 5 | H7: Alternating Bodyweight Split Jump | I7: Legs | J7: 5 | K7: https://www.youtube.com/watch?v=ZiupDCper-M | L7: Jump and switch legs, working lower body power.
A8: 6 | B8: 15 - 20 | C8: 90s | D8: F | E8: 1114 | F8: 6 | H8: Alternating Dumbbell Bench Press | I8: Chest | J8: 6 | K8: https://www.youtube.com/watch?v=p8A3oaWhU6U | L8: Press dumbbells alternately while lying on bench.
A9: 7 | B9: 20 - 25 | C9: 2 mins | D9: G | E9: 1115 | F9: 7 | H9: Alternating Dumbbell Curl | I9: Arms | J9: 7 | K9: https://www.youtube.com/watch?v=iixND1P2lik | L9: Curl dumbbells alternately to work biceps.
A10: 8 | B10: 30s | C10: 3 mins | D10: H | E10: 1116 | F10: 8 | H10: Alternating Dumbell Split Jump | I10: Legs | J10: 8 | K10: https://www.youtube.com/watch?v=e3hCZpHeEZ4 | L10: Jump and switch legs, holding dumbbells.
A11: 9 | B11: 45s | C11: 4 mins | D11: I | E11: 1121 | F11: 9 | H11: Alternating Lateral Lunge Walk | I11: Legs | J11: 9 | K11: https://www.youtube.com/watch?v=-mLAtXQLiTE | L11: Step laterally, alternating sides, engaging leg muscles.
A12: 10 | B12: 60s | C12: 5 mins | E12: 1122 | F12: 10 | H12: Alternating Single Leg V-Up | I12: Core | J12: 10 | K12: https://www.youtube.com/watch?v=0EIDVDbzVNo | L12: Lift alternating legs while performing V-Up motion.
A13: 11 | B13: 2 mins | C13: -- | E13: 1123 | F13: 11 | H13: American KB Swing | I13: Back, Shoulders | J13: 11 | K13: https://www.youtube.com/watch?v=E6GoQYuZZT4 | L13: Swing kettlebell overhead, engaging core and hips.
A14: 12 | B14: 3 mins | E14: 1124 | F14: 12 | H14: Anchored Reverse Crunch | I14: Core | J14: 12 | K14: https://www.youtube.com/watch?v=fcvdXzWoogg | L14: Crunch upward while keeping legs anchored.
B15: 5 mins | E15: 1125 | F15: 13 | H15: Anchored Sit Up | I15: Core | J15: 13 | K15: https://www.youtube.com/watch?v=CBL_WRQjvuY | L15: Perform sit-up while keeping feet anchored.
E16: 1126 | F16: 14 | H16: Anderson Front Squat | I16: Legs | J16: 14 | K16: https://www.youtube.com/watch?v=wFbJajvBZzY | L16: Squat from pins, starting at the bottom.
E17: 1131 | F17: 15 | H17: Anti-Rotation Core Activation | I17: Core | J17: 15 | K17: https://www.youtube.com/watch?v=8KNHP0mN9Lc | L17: Resist rotation to engage core muscles.
E18: 1132 | F18: 16 | H18: Archer Squats | I18: Legs | J18: 16 | K18: https://www.youtube.com/watch?v=p4tsleylZB8 | L18: Squat, alternating side lunges to challenge legs.
E19: 1133 | F19: 17 | H19: Arms Across Stretch | I19: Arms, Shoulders | J19: 17 | K19: https://www.youtube.com/watch?v=-1K0m5ywRcY | L19: Stretch arms across chest to release tension.
E20: 1134 | F20: 18 | H20: Arnold Press | I20: Shoulders | J20: 18 | K20: https://www.youtube.com/watch?v=3ml7BH7mNwQ | L20: Press dumbbells overhead, rotating palms as you press.
E21: 1135 | F21: 19 | H21: Arnold Shoulder Press | I21: Shoulders | J21: 19 | K21: https://www.youtube.com/watch?v=6Z15_WdXmVw | L21: Shoulder press with palms rotating inward.
E22: 1136 | F22: 20 | H22: Around the World Squat | I22: Legs | J22: 20 | K22: https://www.youtube.com/watch?v=xbj6TtFJgIY | L22: Squat while moving weight in circular motion.
E23: 1141 | H23: Around the Worlds (weight optional) | I23: Core | J23: 21 | K23: https://www.youtube.com/watch?v=9uqGfOvtqn0 | L23: Rotate arms holding weight around body.
E24: 1142 | H24: Assisted Bodyweight Squat to Box | I24: Legs | J24: 22 | K24: https://www.youtube.com/watch?v=WnADyvqlfDg | L24: Squat with assistance to a box for controlled movement.
E25: 1143 | H25: Assisted Chin-Ups | I25: Back | J25: 23 | K25: https://www.youtube.com/watch?v=A-uiFTIsgRg | L25: Use assistance to perform chin-ups.
E26: 1144 | H26: Assisted Lateral Squat | I26: Legs | J26: 24 | K26: https://www.youtube.com/watch?v=wTQ_wwE-ZuI | L26: Squat laterally with assistance for balance.
E27: 1145 | H27: Assisted Nordic Curls | I27: Legs | J27: 25 | K27: https://www.youtube.com/watch?v=49Uozp9wfik | L27: Perform Nordic curls with assistance to target hamstrings.
E28: 1146 | H28: Assisted Pull-ups | I28: Back | J28: 26 | K28: https://www.youtube.com/watch?v=wFj808u2HWU | L28: Use assistance to perform pull-ups.
E29: 1151 | H29: Assisted Reverse Lunge With Blocked Knee | I29: Legs | J29: 27 | K29: https://www.youtube.com/watch?v=a2BOfZ1Ll8E | L29: Lunge back with assistance, block knee at floor.
E30: 1152 | H30: Back Extension | I30: Back | J30: 28 | K30: https://www.youtube.com/watch?v=H8Swl1N-uis | L30: Engage lower back muscles by lifting torso off the floor.
E31: 1153 | H31: Back Extension to Y's | I31: Back | J31: 29 | K31: https://www.youtube.com/watch?v=ph3pddpKzzw&pp=ygUVQmFjayBFeHRlbnNpb24gdG8gWSdz | L31: Extend arms to form a Y shape while lifting torso.
E32: 1154 | H32: Back Lunge into Kickback | I32: Legs | J32: 30 | K32: https://www.youtube.com/watch?v=rkpvx4DuJJI&pp=ygUYQmFjayBMdW5nZSBpbnRvIEtpY2tiYWNr | L32: Lunge back, then kick back while engaging glutes.
E33: 1155 | H33: Back Squat | I33: Legs | J33: 31 | K33: https://www.youtube.com/watch?v=ultWZbUMPL8&pp=ygUKQmFjayBTcXVhdA%3D%3D | L33: Place barbell on shoulders, squat while keeping form.
E34: 1156 | H34: Back-Supported Pullover | I34: Back | J34: 32 | K34: https://www.youtube.com/watch?v=FK4rHfWKEac&pp=ygUXQmFjay1TdXBwb3J0ZWQgUHVsbG92ZXI%3D | L34: Engage upper back and chest while extending arms.
... E495: 3245 | H495: Heel Elevated Barbell Squat | I495: Legs | J495: 492 | K495: https://www.youtube.com/shorts/gslEzVggur8 | L495: Engage legs and glutes with squats using elevated heels.
E496: 3246 | H496: Heel Elevated Front Squat | I496: Legs | J496: 1228 | K496: https://youtu.be/s8Hx4udb96M?si=kEu3ZcQWB51xVOLT
E497: 3251 | H497: Heel Elevated Single Hip Thrust | I497: Glutes | J497: 493 | K497: https://www.youtube.com/watch?v=YZW3mw_h_DA&pp=ygUfSGVlbCBFbGV2YXRlZCBTaW5nbGUgSGlwIFRocnVzdA%3D%3D | L497: Perform single hip thrusts with elevated heels for glute engagement.
E498: 3252 | H498: Heel Elevated Step Down | I498: Legs | J498: 494 | K498: https://www.youtube.com/watch?v=mJOCFguZRUE&pp=ygUXSGVlbCBFbGV2YXRlZCBTdGVwIERvd24%3D | L498: Engage leg muscles with step-down exercise using elevated heels.
E499: 3253 | H499: Heel Taps | I499: Cardio | J499: 495 | K499: https://www.youtube.com/watch?v=YIOIGUQMck8&pp=ygUJSGVlbCBUYXBz | L499: Perform heel taps exercise to engage core muscles.
E500: 3254 | H500: Heels Elevated Sumo Squat Pulses | I500: Legs | J500: 496 | K500: https://www.youtube.com/watch?v=iPcEh_orLxI&pp=ygUgSGVlbHMgRWxldmF0ZWQgU3VtbyBTcXVhdCBQdWxzZXM%3D | L500: Engage legs and glutes with sumo squat pulses using elevated heels.
...
